[2022-02-04 16:04:21,031] {processor.py:163} INFO - Started process (PID=34) to work on /opt/airflow/dags/example.py
[2022-02-04 16:04:21,033] {processor.py:642} INFO - Processing file /opt/airflow/dags/example.py for tasks to queue
[2022-02-04 16:04:21,033] {logging_mixin.py:109} INFO - [2022-02-04 16:04:21,033] {dagbag.py:500} INFO - Filling up the DagBag from /opt/airflow/dags/example.py
[2022-02-04 16:04:21,076] {processor.py:654} INFO - DAG(s) dict_keys(['example_python_operator']) retrieved from /opt/airflow/dags/example.py
[2022-02-04 16:04:21,577] {logging_mixin.py:109} INFO - [2022-02-04 16:04:21,577] {dag.py:2396} INFO - Sync 1 DAGs
[2022-02-04 16:04:21,593] {logging_mixin.py:109} INFO - [2022-02-04 16:04:21,593] {dag.py:2935} INFO - Setting next_dagrun for example_python_operator to 2019-12-02T00:00:00+00:00
[2022-02-04 16:04:21,594] {processor.py:174} ERROR - Got an exception! Propagating...
Traceback (most recent call last):
  File "/home/airflow/.local/lib/python3.6/site-packages/airflow/dag_processing/processor.py", line 168, in _run_file_processor
    callback_requests=callback_requests,
  File "/home/airflow/.local/lib/python3.6/site-packages/airflow/utils/session.py", line 70, in wrapper
    return func(*args, session=session, **kwargs)
  File "/home/airflow/.local/lib/python3.6/site-packages/airflow/dag_processing/processor.py", line 663, in process_file
    dagbag.sync_to_db()
  File "/home/airflow/.local/lib/python3.6/site-packages/airflow/utils/session.py", line 70, in wrapper
    return func(*args, session=session, **kwargs)
  File "/home/airflow/.local/lib/python3.6/site-packages/airflow/models/dagbag.py", line 608, in sync_to_db
    for attempt in run_with_db_retries(logger=self.log):
  File "/home/airflow/.local/lib/python3.6/site-packages/tenacity/__init__.py", line 382, in __iter__
    do = self.iter(retry_state=retry_state)
  File "/home/airflow/.local/lib/python3.6/site-packages/tenacity/__init__.py", line 349, in iter
    return fut.result()
  File "/usr/local/lib/python3.6/concurrent/futures/_base.py", line 425, in result
    return self.__get_result()
  File "/usr/local/lib/python3.6/concurrent/futures/_base.py", line 384, in __get_result
    raise self._exception
  File "/home/airflow/.local/lib/python3.6/site-packages/airflow/models/dagbag.py", line 622, in sync_to_db
    DAG.bulk_write_to_db(self.dags.values(), session=session)
  File "/home/airflow/.local/lib/python3.6/site-packages/airflow/utils/session.py", line 67, in wrapper
    return func(*args, **kwargs)
  File "/home/airflow/.local/lib/python3.6/site-packages/airflow/models/dag.py", line 2474, in bulk_write_to_db
    if orm_tag.name not in set(dag.tags):
TypeError: 'NoneType' object is not iterable
[2022-02-04 16:04:51,668] {processor.py:163} INFO - Started process (PID=66) to work on /opt/airflow/dags/example.py
[2022-02-04 16:04:51,671] {processor.py:642} INFO - Processing file /opt/airflow/dags/example.py for tasks to queue
[2022-02-04 16:04:51,672] {logging_mixin.py:109} INFO - [2022-02-04 16:04:51,672] {dagbag.py:500} INFO - Filling up the DagBag from /opt/airflow/dags/example.py
[2022-02-04 16:04:51,701] {processor.py:654} INFO - DAG(s) dict_keys(['example_python_operator']) retrieved from /opt/airflow/dags/example.py
[2022-02-04 16:04:51,903] {logging_mixin.py:109} INFO - [2022-02-04 16:04:51,903] {dag.py:2396} INFO - Sync 1 DAGs
[2022-02-04 16:04:51,915] {logging_mixin.py:109} INFO - [2022-02-04 16:04:51,915] {dag.py:2935} INFO - Setting next_dagrun for example_python_operator to 2019-12-02T00:00:00+00:00
[2022-02-04 16:04:51,915] {processor.py:174} ERROR - Got an exception! Propagating...
Traceback (most recent call last):
  File "/home/airflow/.local/lib/python3.6/site-packages/airflow/dag_processing/processor.py", line 168, in _run_file_processor
    callback_requests=callback_requests,
  File "/home/airflow/.local/lib/python3.6/site-packages/airflow/utils/session.py", line 70, in wrapper
    return func(*args, session=session, **kwargs)
  File "/home/airflow/.local/lib/python3.6/site-packages/airflow/dag_processing/processor.py", line 663, in process_file
    dagbag.sync_to_db()
  File "/home/airflow/.local/lib/python3.6/site-packages/airflow/utils/session.py", line 70, in wrapper
    return func(*args, session=session, **kwargs)
  File "/home/airflow/.local/lib/python3.6/site-packages/airflow/models/dagbag.py", line 608, in sync_to_db
    for attempt in run_with_db_retries(logger=self.log):
  File "/home/airflow/.local/lib/python3.6/site-packages/tenacity/__init__.py", line 382, in __iter__
    do = self.iter(retry_state=retry_state)
  File "/home/airflow/.local/lib/python3.6/site-packages/tenacity/__init__.py", line 349, in iter
    return fut.result()
  File "/usr/local/lib/python3.6/concurrent/futures/_base.py", line 425, in result
    return self.__get_result()
  File "/usr/local/lib/python3.6/concurrent/futures/_base.py", line 384, in __get_result
    raise self._exception
  File "/home/airflow/.local/lib/python3.6/site-packages/airflow/models/dagbag.py", line 622, in sync_to_db
    DAG.bulk_write_to_db(self.dags.values(), session=session)
  File "/home/airflow/.local/lib/python3.6/site-packages/airflow/utils/session.py", line 67, in wrapper
    return func(*args, **kwargs)
  File "/home/airflow/.local/lib/python3.6/site-packages/airflow/models/dag.py", line 2474, in bulk_write_to_db
    if orm_tag.name not in set(dag.tags):
TypeError: 'NoneType' object is not iterable
[2022-02-04 16:05:21,987] {processor.py:163} INFO - Started process (PID=88) to work on /opt/airflow/dags/example.py
[2022-02-04 16:05:21,994] {processor.py:642} INFO - Processing file /opt/airflow/dags/example.py for tasks to queue
[2022-02-04 16:05:21,995] {logging_mixin.py:109} INFO - [2022-02-04 16:05:21,995] {dagbag.py:500} INFO - Filling up the DagBag from /opt/airflow/dags/example.py
[2022-02-04 16:05:22,036] {processor.py:654} INFO - DAG(s) dict_keys(['example_python_operator']) retrieved from /opt/airflow/dags/example.py
[2022-02-04 16:05:22,189] {logging_mixin.py:109} INFO - [2022-02-04 16:05:22,189] {dag.py:2396} INFO - Sync 1 DAGs
[2022-02-04 16:05:22,201] {logging_mixin.py:109} INFO - [2022-02-04 16:05:22,201] {dag.py:2935} INFO - Setting next_dagrun for example_python_operator to 2019-12-02T00:00:00+00:00
[2022-02-04 16:05:22,202] {processor.py:174} ERROR - Got an exception! Propagating...
Traceback (most recent call last):
  File "/home/airflow/.local/lib/python3.6/site-packages/airflow/dag_processing/processor.py", line 168, in _run_file_processor
    callback_requests=callback_requests,
  File "/home/airflow/.local/lib/python3.6/site-packages/airflow/utils/session.py", line 70, in wrapper
    return func(*args, session=session, **kwargs)
  File "/home/airflow/.local/lib/python3.6/site-packages/airflow/dag_processing/processor.py", line 663, in process_file
    dagbag.sync_to_db()
  File "/home/airflow/.local/lib/python3.6/site-packages/airflow/utils/session.py", line 70, in wrapper
    return func(*args, session=session, **kwargs)
  File "/home/airflow/.local/lib/python3.6/site-packages/airflow/models/dagbag.py", line 608, in sync_to_db
    for attempt in run_with_db_retries(logger=self.log):
  File "/home/airflow/.local/lib/python3.6/site-packages/tenacity/__init__.py", line 382, in __iter__
    do = self.iter(retry_state=retry_state)
  File "/home/airflow/.local/lib/python3.6/site-packages/tenacity/__init__.py", line 349, in iter
    return fut.result()
  File "/usr/local/lib/python3.6/concurrent/futures/_base.py", line 425, in result
    return self.__get_result()
  File "/usr/local/lib/python3.6/concurrent/futures/_base.py", line 384, in __get_result
    raise self._exception
  File "/home/airflow/.local/lib/python3.6/site-packages/airflow/models/dagbag.py", line 622, in sync_to_db
    DAG.bulk_write_to_db(self.dags.values(), session=session)
  File "/home/airflow/.local/lib/python3.6/site-packages/airflow/utils/session.py", line 67, in wrapper
    return func(*args, **kwargs)
  File "/home/airflow/.local/lib/python3.6/site-packages/airflow/models/dag.py", line 2474, in bulk_write_to_db
    if orm_tag.name not in set(dag.tags):
TypeError: 'NoneType' object is not iterable
[2022-02-04 16:05:52,257] {processor.py:163} INFO - Started process (PID=120) to work on /opt/airflow/dags/example.py
[2022-02-04 16:05:52,258] {processor.py:642} INFO - Processing file /opt/airflow/dags/example.py for tasks to queue
[2022-02-04 16:05:52,259] {logging_mixin.py:109} INFO - [2022-02-04 16:05:52,259] {dagbag.py:500} INFO - Filling up the DagBag from /opt/airflow/dags/example.py
[2022-02-04 16:05:52,289] {processor.py:654} INFO - DAG(s) dict_keys(['example_python_operator']) retrieved from /opt/airflow/dags/example.py
[2022-02-04 16:05:52,463] {logging_mixin.py:109} INFO - [2022-02-04 16:05:52,463] {dag.py:2396} INFO - Sync 1 DAGs
[2022-02-04 16:05:52,476] {logging_mixin.py:109} INFO - [2022-02-04 16:05:52,476] {dag.py:2935} INFO - Setting next_dagrun for example_python_operator to 2019-12-02T00:00:00+00:00
[2022-02-04 16:05:52,477] {processor.py:174} ERROR - Got an exception! Propagating...
Traceback (most recent call last):
  File "/home/airflow/.local/lib/python3.6/site-packages/airflow/dag_processing/processor.py", line 168, in _run_file_processor
    callback_requests=callback_requests,
  File "/home/airflow/.local/lib/python3.6/site-packages/airflow/utils/session.py", line 70, in wrapper
    return func(*args, session=session, **kwargs)
  File "/home/airflow/.local/lib/python3.6/site-packages/airflow/dag_processing/processor.py", line 663, in process_file
    dagbag.sync_to_db()
  File "/home/airflow/.local/lib/python3.6/site-packages/airflow/utils/session.py", line 70, in wrapper
    return func(*args, session=session, **kwargs)
  File "/home/airflow/.local/lib/python3.6/site-packages/airflow/models/dagbag.py", line 608, in sync_to_db
    for attempt in run_with_db_retries(logger=self.log):
  File "/home/airflow/.local/lib/python3.6/site-packages/tenacity/__init__.py", line 382, in __iter__
    do = self.iter(retry_state=retry_state)
  File "/home/airflow/.local/lib/python3.6/site-packages/tenacity/__init__.py", line 349, in iter
    return fut.result()
  File "/usr/local/lib/python3.6/concurrent/futures/_base.py", line 425, in result
    return self.__get_result()
  File "/usr/local/lib/python3.6/concurrent/futures/_base.py", line 384, in __get_result
    raise self._exception
  File "/home/airflow/.local/lib/python3.6/site-packages/airflow/models/dagbag.py", line 622, in sync_to_db
    DAG.bulk_write_to_db(self.dags.values(), session=session)
  File "/home/airflow/.local/lib/python3.6/site-packages/airflow/utils/session.py", line 67, in wrapper
    return func(*args, **kwargs)
  File "/home/airflow/.local/lib/python3.6/site-packages/airflow/models/dag.py", line 2474, in bulk_write_to_db
    if orm_tag.name not in set(dag.tags):
TypeError: 'NoneType' object is not iterable
[2022-02-04 16:06:22,538] {processor.py:163} INFO - Started process (PID=141) to work on /opt/airflow/dags/example.py
[2022-02-04 16:06:22,541] {processor.py:642} INFO - Processing file /opt/airflow/dags/example.py for tasks to queue
[2022-02-04 16:06:22,542] {logging_mixin.py:109} INFO - [2022-02-04 16:06:22,542] {dagbag.py:500} INFO - Filling up the DagBag from /opt/airflow/dags/example.py
[2022-02-04 16:06:22,564] {processor.py:654} INFO - DAG(s) dict_keys(['example_python_operator']) retrieved from /opt/airflow/dags/example.py
[2022-02-04 16:06:22,718] {logging_mixin.py:109} INFO - [2022-02-04 16:06:22,718] {dag.py:2396} INFO - Sync 1 DAGs
[2022-02-04 16:06:22,732] {logging_mixin.py:109} INFO - [2022-02-04 16:06:22,732] {dag.py:2935} INFO - Setting next_dagrun for example_python_operator to 2019-12-02T00:00:00+00:00
[2022-02-04 16:06:22,733] {processor.py:174} ERROR - Got an exception! Propagating...
Traceback (most recent call last):
  File "/home/airflow/.local/lib/python3.6/site-packages/airflow/dag_processing/processor.py", line 168, in _run_file_processor
    callback_requests=callback_requests,
  File "/home/airflow/.local/lib/python3.6/site-packages/airflow/utils/session.py", line 70, in wrapper
    return func(*args, session=session, **kwargs)
  File "/home/airflow/.local/lib/python3.6/site-packages/airflow/dag_processing/processor.py", line 663, in process_file
    dagbag.sync_to_db()
  File "/home/airflow/.local/lib/python3.6/site-packages/airflow/utils/session.py", line 70, in wrapper
    return func(*args, session=session, **kwargs)
  File "/home/airflow/.local/lib/python3.6/site-packages/airflow/models/dagbag.py", line 608, in sync_to_db
    for attempt in run_with_db_retries(logger=self.log):
  File "/home/airflow/.local/lib/python3.6/site-packages/tenacity/__init__.py", line 382, in __iter__
    do = self.iter(retry_state=retry_state)
  File "/home/airflow/.local/lib/python3.6/site-packages/tenacity/__init__.py", line 349, in iter
    return fut.result()
  File "/usr/local/lib/python3.6/concurrent/futures/_base.py", line 425, in result
    return self.__get_result()
  File "/usr/local/lib/python3.6/concurrent/futures/_base.py", line 384, in __get_result
    raise self._exception
  File "/home/airflow/.local/lib/python3.6/site-packages/airflow/models/dagbag.py", line 622, in sync_to_db
    DAG.bulk_write_to_db(self.dags.values(), session=session)
  File "/home/airflow/.local/lib/python3.6/site-packages/airflow/utils/session.py", line 67, in wrapper
    return func(*args, **kwargs)
  File "/home/airflow/.local/lib/python3.6/site-packages/airflow/models/dag.py", line 2474, in bulk_write_to_db
    if orm_tag.name not in set(dag.tags):
TypeError: 'NoneType' object is not iterable
[2022-02-04 16:06:52,808] {processor.py:163} INFO - Started process (PID=162) to work on /opt/airflow/dags/example.py
[2022-02-04 16:06:52,814] {processor.py:642} INFO - Processing file /opt/airflow/dags/example.py for tasks to queue
[2022-02-04 16:06:52,815] {logging_mixin.py:109} INFO - [2022-02-04 16:06:52,815] {dagbag.py:500} INFO - Filling up the DagBag from /opt/airflow/dags/example.py
[2022-02-04 16:06:52,847] {processor.py:654} INFO - DAG(s) dict_keys(['example_python_operator']) retrieved from /opt/airflow/dags/example.py
[2022-02-04 16:06:53,003] {logging_mixin.py:109} INFO - [2022-02-04 16:06:53,003] {dag.py:2396} INFO - Sync 1 DAGs
[2022-02-04 16:06:53,016] {logging_mixin.py:109} INFO - [2022-02-04 16:06:53,015] {dag.py:2935} INFO - Setting next_dagrun for example_python_operator to 2019-12-02T00:00:00+00:00
[2022-02-04 16:06:53,016] {processor.py:174} ERROR - Got an exception! Propagating...
Traceback (most recent call last):
  File "/home/airflow/.local/lib/python3.6/site-packages/airflow/dag_processing/processor.py", line 168, in _run_file_processor
    callback_requests=callback_requests,
  File "/home/airflow/.local/lib/python3.6/site-packages/airflow/utils/session.py", line 70, in wrapper
    return func(*args, session=session, **kwargs)
  File "/home/airflow/.local/lib/python3.6/site-packages/airflow/dag_processing/processor.py", line 663, in process_file
    dagbag.sync_to_db()
  File "/home/airflow/.local/lib/python3.6/site-packages/airflow/utils/session.py", line 70, in wrapper
    return func(*args, session=session, **kwargs)
  File "/home/airflow/.local/lib/python3.6/site-packages/airflow/models/dagbag.py", line 608, in sync_to_db
    for attempt in run_with_db_retries(logger=self.log):
  File "/home/airflow/.local/lib/python3.6/site-packages/tenacity/__init__.py", line 382, in __iter__
    do = self.iter(retry_state=retry_state)
  File "/home/airflow/.local/lib/python3.6/site-packages/tenacity/__init__.py", line 349, in iter
    return fut.result()
  File "/usr/local/lib/python3.6/concurrent/futures/_base.py", line 425, in result
    return self.__get_result()
  File "/usr/local/lib/python3.6/concurrent/futures/_base.py", line 384, in __get_result
    raise self._exception
  File "/home/airflow/.local/lib/python3.6/site-packages/airflow/models/dagbag.py", line 622, in sync_to_db
    DAG.bulk_write_to_db(self.dags.values(), session=session)
  File "/home/airflow/.local/lib/python3.6/site-packages/airflow/utils/session.py", line 67, in wrapper
    return func(*args, **kwargs)
  File "/home/airflow/.local/lib/python3.6/site-packages/airflow/models/dag.py", line 2474, in bulk_write_to_db
    if orm_tag.name not in set(dag.tags):
TypeError: 'NoneType' object is not iterable
[2022-02-04 16:07:23,076] {processor.py:163} INFO - Started process (PID=194) to work on /opt/airflow/dags/example.py
[2022-02-04 16:07:23,080] {processor.py:642} INFO - Processing file /opt/airflow/dags/example.py for tasks to queue
[2022-02-04 16:07:23,080] {logging_mixin.py:109} INFO - [2022-02-04 16:07:23,080] {dagbag.py:500} INFO - Filling up the DagBag from /opt/airflow/dags/example.py
[2022-02-04 16:07:23,102] {processor.py:654} INFO - DAG(s) dict_keys(['example_python_operator']) retrieved from /opt/airflow/dags/example.py
[2022-02-04 16:07:23,265] {logging_mixin.py:109} INFO - [2022-02-04 16:07:23,265] {dag.py:2396} INFO - Sync 1 DAGs
[2022-02-04 16:07:23,279] {logging_mixin.py:109} INFO - [2022-02-04 16:07:23,279] {dag.py:2935} INFO - Setting next_dagrun for example_python_operator to 2019-12-02T00:00:00+00:00
[2022-02-04 16:07:23,280] {processor.py:174} ERROR - Got an exception! Propagating...
Traceback (most recent call last):
  File "/home/airflow/.local/lib/python3.6/site-packages/airflow/dag_processing/processor.py", line 168, in _run_file_processor
    callback_requests=callback_requests,
  File "/home/airflow/.local/lib/python3.6/site-packages/airflow/utils/session.py", line 70, in wrapper
    return func(*args, session=session, **kwargs)
  File "/home/airflow/.local/lib/python3.6/site-packages/airflow/dag_processing/processor.py", line 663, in process_file
    dagbag.sync_to_db()
  File "/home/airflow/.local/lib/python3.6/site-packages/airflow/utils/session.py", line 70, in wrapper
    return func(*args, session=session, **kwargs)
  File "/home/airflow/.local/lib/python3.6/site-packages/airflow/models/dagbag.py", line 608, in sync_to_db
    for attempt in run_with_db_retries(logger=self.log):
  File "/home/airflow/.local/lib/python3.6/site-packages/tenacity/__init__.py", line 382, in __iter__
    do = self.iter(retry_state=retry_state)
  File "/home/airflow/.local/lib/python3.6/site-packages/tenacity/__init__.py", line 349, in iter
    return fut.result()
  File "/usr/local/lib/python3.6/concurrent/futures/_base.py", line 425, in result
    return self.__get_result()
  File "/usr/local/lib/python3.6/concurrent/futures/_base.py", line 384, in __get_result
    raise self._exception
  File "/home/airflow/.local/lib/python3.6/site-packages/airflow/models/dagbag.py", line 622, in sync_to_db
    DAG.bulk_write_to_db(self.dags.values(), session=session)
  File "/home/airflow/.local/lib/python3.6/site-packages/airflow/utils/session.py", line 67, in wrapper
    return func(*args, **kwargs)
  File "/home/airflow/.local/lib/python3.6/site-packages/airflow/models/dag.py", line 2474, in bulk_write_to_db
    if orm_tag.name not in set(dag.tags):
TypeError: 'NoneType' object is not iterable
[2022-02-04 16:07:53,337] {processor.py:163} INFO - Started process (PID=217) to work on /opt/airflow/dags/example.py
[2022-02-04 16:07:53,338] {processor.py:642} INFO - Processing file /opt/airflow/dags/example.py for tasks to queue
[2022-02-04 16:07:53,338] {logging_mixin.py:109} INFO - [2022-02-04 16:07:53,338] {dagbag.py:500} INFO - Filling up the DagBag from /opt/airflow/dags/example.py
[2022-02-04 16:07:53,361] {processor.py:654} INFO - DAG(s) dict_keys(['example_python_operator']) retrieved from /opt/airflow/dags/example.py
[2022-02-04 16:07:53,528] {logging_mixin.py:109} INFO - [2022-02-04 16:07:53,528] {dag.py:2396} INFO - Sync 1 DAGs
[2022-02-04 16:07:53,541] {logging_mixin.py:109} INFO - [2022-02-04 16:07:53,541] {dag.py:2935} INFO - Setting next_dagrun for example_python_operator to 2019-12-02T00:00:00+00:00
[2022-02-04 16:07:53,542] {processor.py:174} ERROR - Got an exception! Propagating...
Traceback (most recent call last):
  File "/home/airflow/.local/lib/python3.6/site-packages/airflow/dag_processing/processor.py", line 168, in _run_file_processor
    callback_requests=callback_requests,
  File "/home/airflow/.local/lib/python3.6/site-packages/airflow/utils/session.py", line 70, in wrapper
    return func(*args, session=session, **kwargs)
  File "/home/airflow/.local/lib/python3.6/site-packages/airflow/dag_processing/processor.py", line 663, in process_file
    dagbag.sync_to_db()
  File "/home/airflow/.local/lib/python3.6/site-packages/airflow/utils/session.py", line 70, in wrapper
    return func(*args, session=session, **kwargs)
  File "/home/airflow/.local/lib/python3.6/site-packages/airflow/models/dagbag.py", line 608, in sync_to_db
    for attempt in run_with_db_retries(logger=self.log):
  File "/home/airflow/.local/lib/python3.6/site-packages/tenacity/__init__.py", line 382, in __iter__
    do = self.iter(retry_state=retry_state)
  File "/home/airflow/.local/lib/python3.6/site-packages/tenacity/__init__.py", line 349, in iter
    return fut.result()
  File "/usr/local/lib/python3.6/concurrent/futures/_base.py", line 425, in result
    return self.__get_result()
  File "/usr/local/lib/python3.6/concurrent/futures/_base.py", line 384, in __get_result
    raise self._exception
  File "/home/airflow/.local/lib/python3.6/site-packages/airflow/models/dagbag.py", line 622, in sync_to_db
    DAG.bulk_write_to_db(self.dags.values(), session=session)
  File "/home/airflow/.local/lib/python3.6/site-packages/airflow/utils/session.py", line 67, in wrapper
    return func(*args, **kwargs)
  File "/home/airflow/.local/lib/python3.6/site-packages/airflow/models/dag.py", line 2474, in bulk_write_to_db
    if orm_tag.name not in set(dag.tags):
TypeError: 'NoneType' object is not iterable
[2022-02-04 16:08:23,599] {processor.py:163} INFO - Started process (PID=249) to work on /opt/airflow/dags/example.py
[2022-02-04 16:08:23,600] {processor.py:642} INFO - Processing file /opt/airflow/dags/example.py for tasks to queue
[2022-02-04 16:08:23,601] {logging_mixin.py:109} INFO - [2022-02-04 16:08:23,600] {dagbag.py:500} INFO - Filling up the DagBag from /opt/airflow/dags/example.py
[2022-02-04 16:08:23,624] {processor.py:654} INFO - DAG(s) dict_keys(['example_python_operator']) retrieved from /opt/airflow/dags/example.py
[2022-02-04 16:08:23,779] {logging_mixin.py:109} INFO - [2022-02-04 16:08:23,779] {dag.py:2396} INFO - Sync 1 DAGs
[2022-02-04 16:08:23,792] {logging_mixin.py:109} INFO - [2022-02-04 16:08:23,792] {dag.py:2935} INFO - Setting next_dagrun for example_python_operator to 2019-12-02T00:00:00+00:00
[2022-02-04 16:08:23,793] {processor.py:174} ERROR - Got an exception! Propagating...
Traceback (most recent call last):
  File "/home/airflow/.local/lib/python3.6/site-packages/airflow/dag_processing/processor.py", line 168, in _run_file_processor
    callback_requests=callback_requests,
  File "/home/airflow/.local/lib/python3.6/site-packages/airflow/utils/session.py", line 70, in wrapper
    return func(*args, session=session, **kwargs)
  File "/home/airflow/.local/lib/python3.6/site-packages/airflow/dag_processing/processor.py", line 663, in process_file
    dagbag.sync_to_db()
  File "/home/airflow/.local/lib/python3.6/site-packages/airflow/utils/session.py", line 70, in wrapper
    return func(*args, session=session, **kwargs)
  File "/home/airflow/.local/lib/python3.6/site-packages/airflow/models/dagbag.py", line 608, in sync_to_db
    for attempt in run_with_db_retries(logger=self.log):
  File "/home/airflow/.local/lib/python3.6/site-packages/tenacity/__init__.py", line 382, in __iter__
    do = self.iter(retry_state=retry_state)
  File "/home/airflow/.local/lib/python3.6/site-packages/tenacity/__init__.py", line 349, in iter
    return fut.result()
  File "/usr/local/lib/python3.6/concurrent/futures/_base.py", line 425, in result
    return self.__get_result()
  File "/usr/local/lib/python3.6/concurrent/futures/_base.py", line 384, in __get_result
    raise self._exception
  File "/home/airflow/.local/lib/python3.6/site-packages/airflow/models/dagbag.py", line 622, in sync_to_db
    DAG.bulk_write_to_db(self.dags.values(), session=session)
  File "/home/airflow/.local/lib/python3.6/site-packages/airflow/utils/session.py", line 67, in wrapper
    return func(*args, **kwargs)
  File "/home/airflow/.local/lib/python3.6/site-packages/airflow/models/dag.py", line 2474, in bulk_write_to_db
    if orm_tag.name not in set(dag.tags):
TypeError: 'NoneType' object is not iterable
[2022-02-04 16:08:53,857] {processor.py:163} INFO - Started process (PID=270) to work on /opt/airflow/dags/example.py
[2022-02-04 16:08:53,858] {processor.py:642} INFO - Processing file /opt/airflow/dags/example.py for tasks to queue
[2022-02-04 16:08:53,858] {logging_mixin.py:109} INFO - [2022-02-04 16:08:53,858] {dagbag.py:500} INFO - Filling up the DagBag from /opt/airflow/dags/example.py
[2022-02-04 16:08:53,883] {processor.py:654} INFO - DAG(s) dict_keys(['example_python_operator']) retrieved from /opt/airflow/dags/example.py
[2022-02-04 16:08:54,050] {logging_mixin.py:109} INFO - [2022-02-04 16:08:54,050] {dag.py:2396} INFO - Sync 1 DAGs
[2022-02-04 16:08:54,063] {logging_mixin.py:109} INFO - [2022-02-04 16:08:54,063] {dag.py:2935} INFO - Setting next_dagrun for example_python_operator to 2019-12-02T00:00:00+00:00
[2022-02-04 16:08:54,063] {processor.py:174} ERROR - Got an exception! Propagating...
Traceback (most recent call last):
  File "/home/airflow/.local/lib/python3.6/site-packages/airflow/dag_processing/processor.py", line 168, in _run_file_processor
    callback_requests=callback_requests,
  File "/home/airflow/.local/lib/python3.6/site-packages/airflow/utils/session.py", line 70, in wrapper
    return func(*args, session=session, **kwargs)
  File "/home/airflow/.local/lib/python3.6/site-packages/airflow/dag_processing/processor.py", line 663, in process_file
    dagbag.sync_to_db()
  File "/home/airflow/.local/lib/python3.6/site-packages/airflow/utils/session.py", line 70, in wrapper
    return func(*args, session=session, **kwargs)
  File "/home/airflow/.local/lib/python3.6/site-packages/airflow/models/dagbag.py", line 608, in sync_to_db
    for attempt in run_with_db_retries(logger=self.log):
  File "/home/airflow/.local/lib/python3.6/site-packages/tenacity/__init__.py", line 382, in __iter__
    do = self.iter(retry_state=retry_state)
  File "/home/airflow/.local/lib/python3.6/site-packages/tenacity/__init__.py", line 349, in iter
    return fut.result()
  File "/usr/local/lib/python3.6/concurrent/futures/_base.py", line 425, in result
    return self.__get_result()
  File "/usr/local/lib/python3.6/concurrent/futures/_base.py", line 384, in __get_result
    raise self._exception
  File "/home/airflow/.local/lib/python3.6/site-packages/airflow/models/dagbag.py", line 622, in sync_to_db
    DAG.bulk_write_to_db(self.dags.values(), session=session)
  File "/home/airflow/.local/lib/python3.6/site-packages/airflow/utils/session.py", line 67, in wrapper
    return func(*args, **kwargs)
  File "/home/airflow/.local/lib/python3.6/site-packages/airflow/models/dag.py", line 2474, in bulk_write_to_db
    if orm_tag.name not in set(dag.tags):
TypeError: 'NoneType' object is not iterable
[2022-02-04 16:09:24,166] {processor.py:163} INFO - Started process (PID=291) to work on /opt/airflow/dags/example.py
[2022-02-04 16:09:24,171] {processor.py:642} INFO - Processing file /opt/airflow/dags/example.py for tasks to queue
[2022-02-04 16:09:24,172] {logging_mixin.py:109} INFO - [2022-02-04 16:09:24,172] {dagbag.py:500} INFO - Filling up the DagBag from /opt/airflow/dags/example.py
[2022-02-04 16:09:24,204] {processor.py:654} INFO - DAG(s) dict_keys(['example_python_operator']) retrieved from /opt/airflow/dags/example.py
[2022-02-04 16:09:24,362] {logging_mixin.py:109} INFO - [2022-02-04 16:09:24,362] {dag.py:2396} INFO - Sync 1 DAGs
[2022-02-04 16:09:24,374] {logging_mixin.py:109} INFO - [2022-02-04 16:09:24,374] {dag.py:2935} INFO - Setting next_dagrun for example_python_operator to 2019-12-02T00:00:00+00:00
[2022-02-04 16:09:24,375] {processor.py:174} ERROR - Got an exception! Propagating...
Traceback (most recent call last):
  File "/home/airflow/.local/lib/python3.6/site-packages/airflow/dag_processing/processor.py", line 168, in _run_file_processor
    callback_requests=callback_requests,
  File "/home/airflow/.local/lib/python3.6/site-packages/airflow/utils/session.py", line 70, in wrapper
    return func(*args, session=session, **kwargs)
  File "/home/airflow/.local/lib/python3.6/site-packages/airflow/dag_processing/processor.py", line 663, in process_file
    dagbag.sync_to_db()
  File "/home/airflow/.local/lib/python3.6/site-packages/airflow/utils/session.py", line 70, in wrapper
    return func(*args, session=session, **kwargs)
  File "/home/airflow/.local/lib/python3.6/site-packages/airflow/models/dagbag.py", line 608, in sync_to_db
    for attempt in run_with_db_retries(logger=self.log):
  File "/home/airflow/.local/lib/python3.6/site-packages/tenacity/__init__.py", line 382, in __iter__
    do = self.iter(retry_state=retry_state)
  File "/home/airflow/.local/lib/python3.6/site-packages/tenacity/__init__.py", line 349, in iter
    return fut.result()
  File "/usr/local/lib/python3.6/concurrent/futures/_base.py", line 425, in result
    return self.__get_result()
  File "/usr/local/lib/python3.6/concurrent/futures/_base.py", line 384, in __get_result
    raise self._exception
  File "/home/airflow/.local/lib/python3.6/site-packages/airflow/models/dagbag.py", line 622, in sync_to_db
    DAG.bulk_write_to_db(self.dags.values(), session=session)
  File "/home/airflow/.local/lib/python3.6/site-packages/airflow/utils/session.py", line 67, in wrapper
    return func(*args, **kwargs)
  File "/home/airflow/.local/lib/python3.6/site-packages/airflow/models/dag.py", line 2474, in bulk_write_to_db
    if orm_tag.name not in set(dag.tags):
TypeError: 'NoneType' object is not iterable
[2022-02-04 16:09:54,457] {processor.py:163} INFO - Started process (PID=322) to work on /opt/airflow/dags/example.py
[2022-02-04 16:09:54,463] {processor.py:642} INFO - Processing file /opt/airflow/dags/example.py for tasks to queue
[2022-02-04 16:09:54,465] {logging_mixin.py:109} INFO - [2022-02-04 16:09:54,465] {dagbag.py:500} INFO - Filling up the DagBag from /opt/airflow/dags/example.py
[2022-02-04 16:09:54,517] {processor.py:654} INFO - DAG(s) dict_keys(['example_python_operator']) retrieved from /opt/airflow/dags/example.py
[2022-02-04 16:09:54,672] {logging_mixin.py:109} INFO - [2022-02-04 16:09:54,672] {dag.py:2396} INFO - Sync 1 DAGs
[2022-02-04 16:09:54,685] {logging_mixin.py:109} INFO - [2022-02-04 16:09:54,684] {dag.py:2935} INFO - Setting next_dagrun for example_python_operator to 2019-12-02T00:00:00+00:00
[2022-02-04 16:09:54,686] {processor.py:174} ERROR - Got an exception! Propagating...
Traceback (most recent call last):
  File "/home/airflow/.local/lib/python3.6/site-packages/airflow/dag_processing/processor.py", line 168, in _run_file_processor
    callback_requests=callback_requests,
  File "/home/airflow/.local/lib/python3.6/site-packages/airflow/utils/session.py", line 70, in wrapper
    return func(*args, session=session, **kwargs)
  File "/home/airflow/.local/lib/python3.6/site-packages/airflow/dag_processing/processor.py", line 663, in process_file
    dagbag.sync_to_db()
  File "/home/airflow/.local/lib/python3.6/site-packages/airflow/utils/session.py", line 70, in wrapper
    return func(*args, session=session, **kwargs)
  File "/home/airflow/.local/lib/python3.6/site-packages/airflow/models/dagbag.py", line 608, in sync_to_db
    for attempt in run_with_db_retries(logger=self.log):
  File "/home/airflow/.local/lib/python3.6/site-packages/tenacity/__init__.py", line 382, in __iter__
    do = self.iter(retry_state=retry_state)
  File "/home/airflow/.local/lib/python3.6/site-packages/tenacity/__init__.py", line 349, in iter
    return fut.result()
  File "/usr/local/lib/python3.6/concurrent/futures/_base.py", line 425, in result
    return self.__get_result()
  File "/usr/local/lib/python3.6/concurrent/futures/_base.py", line 384, in __get_result
    raise self._exception
  File "/home/airflow/.local/lib/python3.6/site-packages/airflow/models/dagbag.py", line 622, in sync_to_db
    DAG.bulk_write_to_db(self.dags.values(), session=session)
  File "/home/airflow/.local/lib/python3.6/site-packages/airflow/utils/session.py", line 67, in wrapper
    return func(*args, **kwargs)
  File "/home/airflow/.local/lib/python3.6/site-packages/airflow/models/dag.py", line 2474, in bulk_write_to_db
    if orm_tag.name not in set(dag.tags):
TypeError: 'NoneType' object is not iterable
[2022-02-04 16:10:24,751] {processor.py:163} INFO - Started process (PID=344) to work on /opt/airflow/dags/example.py
[2022-02-04 16:10:24,755] {processor.py:642} INFO - Processing file /opt/airflow/dags/example.py for tasks to queue
[2022-02-04 16:10:24,756] {logging_mixin.py:109} INFO - [2022-02-04 16:10:24,756] {dagbag.py:500} INFO - Filling up the DagBag from /opt/airflow/dags/example.py
[2022-02-04 16:10:24,783] {processor.py:654} INFO - DAG(s) dict_keys(['example_python_operator']) retrieved from /opt/airflow/dags/example.py
[2022-02-04 16:10:24,970] {logging_mixin.py:109} INFO - [2022-02-04 16:10:24,970] {dag.py:2396} INFO - Sync 1 DAGs
[2022-02-04 16:10:24,986] {logging_mixin.py:109} INFO - [2022-02-04 16:10:24,986] {dag.py:2935} INFO - Setting next_dagrun for example_python_operator to 2019-12-02T00:00:00+00:00
[2022-02-04 16:10:24,987] {processor.py:174} ERROR - Got an exception! Propagating...
Traceback (most recent call last):
  File "/home/airflow/.local/lib/python3.6/site-packages/airflow/dag_processing/processor.py", line 168, in _run_file_processor
    callback_requests=callback_requests,
  File "/home/airflow/.local/lib/python3.6/site-packages/airflow/utils/session.py", line 70, in wrapper
    return func(*args, session=session, **kwargs)
  File "/home/airflow/.local/lib/python3.6/site-packages/airflow/dag_processing/processor.py", line 663, in process_file
    dagbag.sync_to_db()
  File "/home/airflow/.local/lib/python3.6/site-packages/airflow/utils/session.py", line 70, in wrapper
    return func(*args, session=session, **kwargs)
  File "/home/airflow/.local/lib/python3.6/site-packages/airflow/models/dagbag.py", line 608, in sync_to_db
    for attempt in run_with_db_retries(logger=self.log):
  File "/home/airflow/.local/lib/python3.6/site-packages/tenacity/__init__.py", line 382, in __iter__
    do = self.iter(retry_state=retry_state)
  File "/home/airflow/.local/lib/python3.6/site-packages/tenacity/__init__.py", line 349, in iter
    return fut.result()
  File "/usr/local/lib/python3.6/concurrent/futures/_base.py", line 425, in result
    return self.__get_result()
  File "/usr/local/lib/python3.6/concurrent/futures/_base.py", line 384, in __get_result
    raise self._exception
  File "/home/airflow/.local/lib/python3.6/site-packages/airflow/models/dagbag.py", line 622, in sync_to_db
    DAG.bulk_write_to_db(self.dags.values(), session=session)
  File "/home/airflow/.local/lib/python3.6/site-packages/airflow/utils/session.py", line 67, in wrapper
    return func(*args, **kwargs)
  File "/home/airflow/.local/lib/python3.6/site-packages/airflow/models/dag.py", line 2474, in bulk_write_to_db
    if orm_tag.name not in set(dag.tags):
TypeError: 'NoneType' object is not iterable
[2022-02-04 16:10:55,046] {processor.py:163} INFO - Started process (PID=377) to work on /opt/airflow/dags/example.py
[2022-02-04 16:10:55,049] {processor.py:642} INFO - Processing file /opt/airflow/dags/example.py for tasks to queue
[2022-02-04 16:10:55,050] {logging_mixin.py:109} INFO - [2022-02-04 16:10:55,050] {dagbag.py:500} INFO - Filling up the DagBag from /opt/airflow/dags/example.py
[2022-02-04 16:10:55,073] {processor.py:654} INFO - DAG(s) dict_keys(['example_python_operator']) retrieved from /opt/airflow/dags/example.py
[2022-02-04 16:10:55,229] {logging_mixin.py:109} INFO - [2022-02-04 16:10:55,229] {dag.py:2396} INFO - Sync 1 DAGs
[2022-02-04 16:10:55,241] {logging_mixin.py:109} INFO - [2022-02-04 16:10:55,241] {dag.py:2935} INFO - Setting next_dagrun for example_python_operator to 2019-12-02T00:00:00+00:00
[2022-02-04 16:10:55,242] {processor.py:174} ERROR - Got an exception! Propagating...
Traceback (most recent call last):
  File "/home/airflow/.local/lib/python3.6/site-packages/airflow/dag_processing/processor.py", line 168, in _run_file_processor
    callback_requests=callback_requests,
  File "/home/airflow/.local/lib/python3.6/site-packages/airflow/utils/session.py", line 70, in wrapper
    return func(*args, session=session, **kwargs)
  File "/home/airflow/.local/lib/python3.6/site-packages/airflow/dag_processing/processor.py", line 663, in process_file
    dagbag.sync_to_db()
  File "/home/airflow/.local/lib/python3.6/site-packages/airflow/utils/session.py", line 70, in wrapper
    return func(*args, session=session, **kwargs)
  File "/home/airflow/.local/lib/python3.6/site-packages/airflow/models/dagbag.py", line 608, in sync_to_db
    for attempt in run_with_db_retries(logger=self.log):
  File "/home/airflow/.local/lib/python3.6/site-packages/tenacity/__init__.py", line 382, in __iter__
    do = self.iter(retry_state=retry_state)
  File "/home/airflow/.local/lib/python3.6/site-packages/tenacity/__init__.py", line 349, in iter
    return fut.result()
  File "/usr/local/lib/python3.6/concurrent/futures/_base.py", line 425, in result
    return self.__get_result()
  File "/usr/local/lib/python3.6/concurrent/futures/_base.py", line 384, in __get_result
    raise self._exception
  File "/home/airflow/.local/lib/python3.6/site-packages/airflow/models/dagbag.py", line 622, in sync_to_db
    DAG.bulk_write_to_db(self.dags.values(), session=session)
  File "/home/airflow/.local/lib/python3.6/site-packages/airflow/utils/session.py", line 67, in wrapper
    return func(*args, **kwargs)
  File "/home/airflow/.local/lib/python3.6/site-packages/airflow/models/dag.py", line 2474, in bulk_write_to_db
    if orm_tag.name not in set(dag.tags):
TypeError: 'NoneType' object is not iterable
[2022-02-04 16:11:25,318] {processor.py:163} INFO - Started process (PID=398) to work on /opt/airflow/dags/example.py
[2022-02-04 16:11:25,321] {processor.py:642} INFO - Processing file /opt/airflow/dags/example.py for tasks to queue
[2022-02-04 16:11:25,322] {logging_mixin.py:109} INFO - [2022-02-04 16:11:25,322] {dagbag.py:500} INFO - Filling up the DagBag from /opt/airflow/dags/example.py
[2022-02-04 16:11:25,360] {processor.py:654} INFO - DAG(s) dict_keys(['example_python_operator']) retrieved from /opt/airflow/dags/example.py
[2022-02-04 16:11:25,530] {logging_mixin.py:109} INFO - [2022-02-04 16:11:25,530] {dag.py:2396} INFO - Sync 1 DAGs
[2022-02-04 16:11:25,542] {logging_mixin.py:109} INFO - [2022-02-04 16:11:25,542] {dag.py:2935} INFO - Setting next_dagrun for example_python_operator to 2019-12-02T00:00:00+00:00
[2022-02-04 16:11:25,543] {processor.py:174} ERROR - Got an exception! Propagating...
Traceback (most recent call last):
  File "/home/airflow/.local/lib/python3.6/site-packages/airflow/dag_processing/processor.py", line 168, in _run_file_processor
    callback_requests=callback_requests,
  File "/home/airflow/.local/lib/python3.6/site-packages/airflow/utils/session.py", line 70, in wrapper
    return func(*args, session=session, **kwargs)
  File "/home/airflow/.local/lib/python3.6/site-packages/airflow/dag_processing/processor.py", line 663, in process_file
    dagbag.sync_to_db()
  File "/home/airflow/.local/lib/python3.6/site-packages/airflow/utils/session.py", line 70, in wrapper
    return func(*args, session=session, **kwargs)
  File "/home/airflow/.local/lib/python3.6/site-packages/airflow/models/dagbag.py", line 608, in sync_to_db
    for attempt in run_with_db_retries(logger=self.log):
  File "/home/airflow/.local/lib/python3.6/site-packages/tenacity/__init__.py", line 382, in __iter__
    do = self.iter(retry_state=retry_state)
  File "/home/airflow/.local/lib/python3.6/site-packages/tenacity/__init__.py", line 349, in iter
    return fut.result()
  File "/usr/local/lib/python3.6/concurrent/futures/_base.py", line 425, in result
    return self.__get_result()
  File "/usr/local/lib/python3.6/concurrent/futures/_base.py", line 384, in __get_result
    raise self._exception
  File "/home/airflow/.local/lib/python3.6/site-packages/airflow/models/dagbag.py", line 622, in sync_to_db
    DAG.bulk_write_to_db(self.dags.values(), session=session)
  File "/home/airflow/.local/lib/python3.6/site-packages/airflow/utils/session.py", line 67, in wrapper
    return func(*args, **kwargs)
  File "/home/airflow/.local/lib/python3.6/site-packages/airflow/models/dag.py", line 2474, in bulk_write_to_db
    if orm_tag.name not in set(dag.tags):
TypeError: 'NoneType' object is not iterable
[2022-02-04 16:11:55,619] {processor.py:163} INFO - Started process (PID=419) to work on /opt/airflow/dags/example.py
[2022-02-04 16:11:55,625] {processor.py:642} INFO - Processing file /opt/airflow/dags/example.py for tasks to queue
[2022-02-04 16:11:55,627] {logging_mixin.py:109} INFO - [2022-02-04 16:11:55,627] {dagbag.py:500} INFO - Filling up the DagBag from /opt/airflow/dags/example.py
[2022-02-04 16:11:55,669] {processor.py:654} INFO - DAG(s) dict_keys(['example_python_operator']) retrieved from /opt/airflow/dags/example.py
[2022-02-04 16:11:55,825] {logging_mixin.py:109} INFO - [2022-02-04 16:11:55,825] {dag.py:2396} INFO - Sync 1 DAGs
[2022-02-04 16:11:55,837] {logging_mixin.py:109} INFO - [2022-02-04 16:11:55,837] {dag.py:2935} INFO - Setting next_dagrun for example_python_operator to 2019-12-02T00:00:00+00:00
[2022-02-04 16:11:55,838] {processor.py:174} ERROR - Got an exception! Propagating...
Traceback (most recent call last):
  File "/home/airflow/.local/lib/python3.6/site-packages/airflow/dag_processing/processor.py", line 168, in _run_file_processor
    callback_requests=callback_requests,
  File "/home/airflow/.local/lib/python3.6/site-packages/airflow/utils/session.py", line 70, in wrapper
    return func(*args, session=session, **kwargs)
  File "/home/airflow/.local/lib/python3.6/site-packages/airflow/dag_processing/processor.py", line 663, in process_file
    dagbag.sync_to_db()
  File "/home/airflow/.local/lib/python3.6/site-packages/airflow/utils/session.py", line 70, in wrapper
    return func(*args, session=session, **kwargs)
  File "/home/airflow/.local/lib/python3.6/site-packages/airflow/models/dagbag.py", line 608, in sync_to_db
    for attempt in run_with_db_retries(logger=self.log):
  File "/home/airflow/.local/lib/python3.6/site-packages/tenacity/__init__.py", line 382, in __iter__
    do = self.iter(retry_state=retry_state)
  File "/home/airflow/.local/lib/python3.6/site-packages/tenacity/__init__.py", line 349, in iter
    return fut.result()
  File "/usr/local/lib/python3.6/concurrent/futures/_base.py", line 425, in result
    return self.__get_result()
  File "/usr/local/lib/python3.6/concurrent/futures/_base.py", line 384, in __get_result
    raise self._exception
  File "/home/airflow/.local/lib/python3.6/site-packages/airflow/models/dagbag.py", line 622, in sync_to_db
    DAG.bulk_write_to_db(self.dags.values(), session=session)
  File "/home/airflow/.local/lib/python3.6/site-packages/airflow/utils/session.py", line 67, in wrapper
    return func(*args, **kwargs)
  File "/home/airflow/.local/lib/python3.6/site-packages/airflow/models/dag.py", line 2474, in bulk_write_to_db
    if orm_tag.name not in set(dag.tags):
TypeError: 'NoneType' object is not iterable
